<mujoco model="reconstructed_living_room">
    <compiler angle="degree" coordinate="local" inertiafromgeom="true"/>
    
    <option integrator="RK4" timestep="0.002"/>

    <default>
        <geom friction="2.0 0.5 0.5" rgba="0.8 0.6 0.4 1"/>
        <joint damping="0.8" armature="0.01"/>
        <velocity ctrlrange="-20 20" ctrllimited="true" kv="8"/>
    </default>

    <asset>
        <!-- Textured 3D Mesh of Scanned Room (Visual Only) -->
        <mesh name="room_visual_mesh" file="reconstructed_scene/Living room 01.obj"/>
        <texture name="room_texture" type="2d" file="reconstructed_scene/Living room 01.png"/>
        <material name="room_material" texture="room_texture"/>
        
        <!-- Standard Floor Grid Asset -->
        <texture name="grid" type="2d" builtin="checker" rgb1=".1 .2 .3" rgb2=".2 .3 .4" width="300" height="300" mark="edge" markrgb=".2 .3 .4"/>
        <material name="grid" texture="grid" texrepeat="2 2" texuniform="true"/>
    </asset>

    <worldbody>
        <light directional="true" diffuse=".8 .8 .8" specular=".2 .2 .2" pos="0 0 5" dir="0 0 -1"/>
        
        <!-- 1. Visual-Only Room Mesh (Conclass and Contype disabled) -->
        <geom name="room_mesh_visual" type="mesh" mesh="room_visual_mesh" material="room_material" group="1" contype="0" conaffinity="0"/>
        
        <!-- 2. Physical Floor Collider (Spawned at Z_min) -->
        <geom name="floor_collider" type="plane" pos="0 0 -2.018" size="15 15 0.1" material="grid" friction="2 0.5 0.5" contype="1" conaffinity="1"/>
        
        <!-- 3. Dynamic Targets (Red Ball and Green Cube) -->
        <body name="red_ball" pos="0.97 2.34 -1.87">
            <geom type="sphere" size="0.15" rgba="1 0 0 1" friction="1 0.5 0.5"/>
        </body>
        
        <body name="green_cube" pos="-1.03 2.84 -1.90">
            <geom type="box" size="0.12 0.12 0.12" rgba="0 1 0 1" friction="1 0.5 0.5"/>
        </body>
    
        <!-- Obstacle: sofa -->
        <body name="obstacle_sofa_0" pos="-1.710 1.333 -1.593">
            <geom type="box" size="0.475 1.100 0.425" rgba="0.8 0.4 0.2 0.4" group="0" contype="1" conaffinity="1"/>
        </body>
        <!-- Obstacle: wall -->
        <body name="obstacle_wall_1" pos="-2.110 1.333 0.217">
            <geom type="box" size="0.075 1.365 2.235" rgba="0.8 0.4 0.2 0.4" group="0" contype="1" conaffinity="1"/>
        </body>
        <!-- Obstacle: wall -->
        <body name="obstacle_wall_2" pos="2.040 1.333 0.217">
            <geom type="box" size="0.075 1.365 2.235" rgba="0.8 0.4 0.2 0.4" group="0" contype="1" conaffinity="1"/>
        </body>
        <!-- Obstacle: wall -->
        <body name="obstacle_wall_3" pos="-0.035 0.043 0.217">
            <geom type="box" size="2.150 0.075 2.235" rgba="0.8 0.4 0.2 0.4" group="0" contype="1" conaffinity="1"/>
        </body>
        <!-- Obstacle: wall -->
        <body name="obstacle_wall_4" pos="-0.035 2.623 0.217">
            <geom type="box" size="2.150 0.075 2.235" rgba="0.8 0.4 0.2 0.4" group="0" contype="1" conaffinity="1"/>
        </body>
        <!-- Obstacle: door -->
        <body name="obstacle_door_5" pos="-0.005 0.998 -0.993">
            <geom type="box" size="0.025 0.450 1.025" rgba="0.8 0.4 0.2 0.4" group="0" contype="1" conaffinity="1"/>
        </body>
        <!-- Obstacle: curtains -->
        <body name="obstacle_curtains_6" pos="2.065 1.333 -0.868">
            <geom type="box" size="0.050 0.750 1.150" rgba="0.8 0.4 0.2 0.4" group="0" contype="1" conaffinity="1"/>
        </body>
        <!-- Obstacle: shelf_unit -->
        <body name="obstacle_shelf_unit_7" pos="1.940 2.198 -1.268">
            <geom type="box" size="0.175 0.500 0.750" rgba="0.8 0.4 0.2 0.4" group="0" contype="1" conaffinity="1"/>
        </body>
        <!-- Obstacle: floor -->
        <body name="obstacle_floor_8" pos="-0.035 1.333 -1.968">
            <geom type="box" size="2.150 1.365 0.050" rgba="0.8 0.4 0.2 0.4" group="0" contype="1" conaffinity="1"/>
        </body>
        <!-- Obstacle: ceiling -->
        <body name="obstacle_ceiling_9" pos="-0.035 1.333 2.402">
            <geom type="box" size="2.150 1.365 0.050" rgba="0.8 0.4 0.2 0.4" group="0" contype="1" conaffinity="1"/>
        </body>
        <!-- Wheeled Robot (Spawned in free center space) -->
        <body name="robot" pos="-0.035 1.338 -1.918">
            <joint type="free"/>
            <geom name="chassis" type="box" size="0.2 0.15 0.05" rgba="0.2 0.2 0.8 1"/>
            
            <!-- Camera (Look Forward +X, Up is +Z, Right is -Y) -->
            <camera name="robot_eye" pos="0.18 0 0.08" fovy="75" xyaxes="0 -1 0 0 0 1"/>
            <!-- Visual Camera Eye (Black Lens) -->
            <geom name="camera_lens" type="sphere" pos="0.18 0 0.08" size="0.025" rgba="0.1 0.1 0.1 1"/>
            <geom name="camera_mount" type="box" pos="0.17 0 0.08" size="0.01 0.02 0.02" rgba="0.5 0.5 0.5 1"/>

            <!-- Wheels -->
            <body name="front_left" pos="0.14 0.17 -0.05">
                <joint name="fl_joint" type="hinge" axis="0 1 0"/>
                <geom type="cylinder" size="0.05 0.015" euler="90 0 0" rgba="0.1 0.1 0.1 1"/>
            </body>
            <body name="front_right" pos="0.14 -0.17 -0.05">
                <joint name="fr_joint" type="hinge" axis="0 1 0"/>
                <geom type="cylinder" size="0.05 0.015" euler="90 0 0" rgba="0.1 0.1 0.1 1"/>
            </body>
            <body name="rear_left" pos="-0.14 0.17 -0.05">
                <joint name="rl_joint" type="hinge" axis="0 1 0"/>
                <geom type="cylinder" size="0.05 0.015" euler="90 0 0" rgba="0.1 0.1 0.1 1"/>
            </body>
            <body name="rear_right" pos="-0.14 -0.17 -0.05">
                <joint name="rr_joint" type="hinge" axis="0 1 0"/>
                <geom type="cylinder" size="0.05 0.015" euler="90 0 0" rgba="0.1 0.1 0.1 1"/>
            </body>
        </body>
    </worldbody>

    <actuator>
        <velocity name="drive_fl" joint="fl_joint"/>
        <velocity name="drive_fr" joint="fr_joint"/>
        <velocity name="drive_rl" joint="rl_joint"/>
        <velocity name="drive_rr" joint="rr_joint"/>
    </actuator>
</mujoco>
